<?xml version="1.0"?>
<robot name="cara">

  <!--  Materials -->
  <material name="non_transparent_white">
    <color rgba="1 1 1 1"/>
  </material>

  <material name="blue">
    <color rgba="0 0.8 0.8 0.4"/>
  </material>

  <material name="yellow">
    <color rgba="0.8 0.8 0 0.4"/>
  </material>

  <material name="pink">
    <color rgba="0.5 0 0.5 0.4"/>
  </material>

  <material name="green">
    <color rgba="0 0.7 0 0.4"/>
  </material>

  <!--  Base link -->
  <link name="base_link">
    <visual>
      <origin xyz="0 0 0.25"/>
      <geometry>
        <cylinder length="0.5" radius="0.2"/>
      </geometry>
       <material name="yellow"/>
    </visual>
  </link>

  <!--  Link1 -->
  <link name="link1">
    <visual>
      <origin xyz="1 0 -0.25"/>
      <geometry>
         <box size="2.0 0.4 0.5"/>
      </geometry>
      <material name="blue"/>
    </visual>
  </link>

  <joint name="base_link_to_link1" type="continuous">
    <axis xyz="0 0 1"/>
    <origin xyz="0 0 1"/>
    <parent link="base_link"/>
    <child link="link1"/>
  </joint>

<!--  Visual Link1-->
  <link name="link1_visual">
    <visual>
      <origin xyz="0 0 0"/>
      <geometry>
        <cylinder length="0.5" radius="0.2"/>
      </geometry>
      <material name="blue"/>
    </visual>
  </link>

  <joint name="link1_to_link1_visual" type="fixed">
    <origin xyz="0 0 -0.25"/>
    <parent link="link1"/>
    <child link="link1_visual"/>
  </joint>

<!--  Link 2-->
  <link name="link2">
    <visual>
      <origin xyz="1 0 -0.25"/>
      <geometry>
         <box size="2.0 0.4 0.5"/>
      </geometry>
      <material name="pink"/>
    </visual>
  </link>

  <joint name="link1_to_link2" type="continuous">
    <axis xyz="0 0 1"/>
    <origin xyz="2 0 0"/>
    <parent link="link1"/>
    <child link="link2"/>
  </joint>

<!--  Visual Link2-->
  <link name="link2_visual">
    <visual>
      <origin xyz="0 0 0"/>
      <geometry>
        <cylinder length="0.5" radius="0.2"/>
      </geometry>
      <material name="pink"/>
    </visual>
  </link>

  <joint name="link2_to_link2_visual" type="fixed">
    <origin xyz="0 0 -0.25"/>
    <parent link="link2"/>
    <child link="link2_visual"/>
  </joint>

  <!--  ee link -->
  <link name="ee_link">
    <visual>
      <origin xyz="0 0 -0.5"/>
      <geometry>
<!--        <cylinder length="1" radius="0.1"/>-->
        <mesh filename="package://psr_scara_description/meshes/mitsubishi_miev.dae"/>
      </geometry>
      <material name="non_transparent_white"/>
    </visual>
  </link>

  <joint name="link2_to_ee_link" type="prismatic">
    <axis xyz="0 0 -1"/>
    <limit effort="1000.0" lower="-1" upper="1" velocity="0.5"/>
<!--    <limit effort="1000.0" lower="-1" upper="1" velocity="-0.5"/>-->
<!--    <limit effort="1000.0" lower="1" upper="-1" velocity="0.5"/>-->
    <origin xyz="2 0 0"/>
    <parent link="link2"/>
    <child link="ee_link"/>
  </joint>
</robot>