<?xml version="1.0"?>
<robot name="scara_p3">

  <material name="blue">
    <color rgba="0 0.8 0.8 1"/>
  </material>

  <material name="yellow">
    <color rgba="0.8 0.8 0 1"/>
  </material>

  <material name="pink">
    <color rgba="0.5 0 0.5 1"/>
  </material>

  <material name="green">
    <color rgba="0 0.7 0 1"/>
  </material>

  <link name="base_link">
    <visual>
      <origin xyz="0.0 0.0 0.5" rpy="0 0 0" />
      <geometry>
        <cylinder length="1" radius="0.5"/>
      </geometry>
      <material name="yellow"/>
    </visual>
  </link>

   <link name="link1">
     <visual>
      <origin xyz="2.0 0.0 -0.5" rpy="0 0 0" />
      <geometry>
        <box size="4.0 1 1"/>
      </geometry>
       <material name="blue"/>
    </visual>
  </link>

<!--   <link name="link1_aux">-->
<!--     <visual>-->
<!--      <origin xyz="0.0 0.0 0" rpy="0 0 0" />-->
<!--      <geometry>-->
<!--        <cylinder length="1" radius="0.5"/>-->
<!--      </geometry>-->
<!--       <material name="blue"/>-->
<!--    </visual>-->
<!--  </link>-->

  <joint name="base_link_to_link1" type="continuous">
    <axis xyz="0 0 1"/>
<!--    <limit effort="1000.0" lower="0.0" upper="0.548" velocity="0.5"/>-->
    <origin xyz="0.0 0.0 2.0" rpy="0 0 0" />
    <parent link="base_link"/>
    <child link="link1"/>
  </joint>

<!--  <joint name="link1_to_link1_aux" type="fixed">-->
<!--    <origin xyz="0.0 0.0 -0.5" rpy="0 0 0" />-->
<!--    <parent link="link1"/>-->
<!--    <child link="link1_aux"/>-->
<!--  </joint>-->

<!--  <link name="link2">-->
<!--      <visual>-->
<!--      <origin xyz="0.0 0.0 0" rpy="0 0 0" />-->
<!--      <geometry>-->
<!--&lt;!&ndash;          <box size="4.0 1 1"/>&ndash;&gt;-->
<!--          <mesh filename="package://psr_scara_p3_description/meshes/mitsubishi_miev.dae"/>-->
<!--      </geometry>-->
<!--&lt;!&ndash;       <material name="pink"/>&ndash;&gt;-->
<!--    </visual>-->
<!--  </link>-->

<!--  <joint name="link1_to_link2" type="continuous">-->
<!--    <axis xyz="0 0 1"/>-->
<!--&lt;!&ndash;    <limit effort="1000.0" lower="0.0" upper="0.548" velocity="0.5"/>&ndash;&gt;-->
<!--    <origin xyz="4.0 0.0 0" rpy="0 0 0" />-->
<!--    <parent link="link1"/>-->
<!--    <child link="link2"/>-->
<!--  </joint>-->

</robot>